<?xml version="1.0"?>
<robot name="my_robot_final" xmlns:xacro="http://www.ros.org/wiki/xacro">


<!-- Constants for robot description -->
<xacro:property name="friction" value="2.5" />
<xacro:property name="type_of_joint" value="continuous" />
  

<!--  Gazebo tags -->
<gazebo reference="link1">
	<self_collide>0</self_collide>
	<material>Gazebo/Orange</material>
</gazebo>

<gazebo reference="link2">
	<self_collide>0</self_collide>	
	<material>Gazebo/Blue</material>
</gazebo>

<gazebo reference="link3">
	<self_collide>0</self_collide>	
	<material>Gazebo/Red</material>
</gazebo>

<gazebo reference="link4">
	<mu1>1.0</mu1>
        <mu2>1.0</mu2>
	<self_collide>0</self_collide>    	
	<material>Gazebo/Black</material>
</gazebo>

<gazebo reference="link5">
	<mu1>1.0</mu1>
        <mu2>1.0</mu2>
    	<self_collide>0</self_collide>
	<material>Gazebo/Black</material>
</gazebo>



<!-- Controlling Joints -->
<gazebo>
    <plugin name="gazebo_ros_control" filename="libgazebo_ros_control.so">
      <robotNamespace>/simple_model</robotNamespace>
    </plugin>
  </gazebo>

<transmission name="first_to_second_trans">
    <type>transmission_interface/SimpleTransmission</type>
    <actuator name="motor1">
      <mechanicalReduction>1</mechanicalReduction>
    </actuator>
    <joint name="joint1">
      <hardwareInterface>EffortJointInterface</hardwareInterface>
    </joint>
  </transmission>

<transmission name="second_to_third_trans">
    <type>transmission_interface/SimpleTransmission</type>
    <actuator name="motor2">
      <mechanicalReduction>1</mechanicalReduction>
    </actuator>
    <joint name="joint2">
      <hardwareInterface>EffortJointInterface</hardwareInterface>
    </joint>
  </transmission> 

<transmission name="second_to_third_trans">
    <type>transmission_interface/SimpleTransmission</type>
    <actuator name="motor3">
      <mechanicalReduction>1</mechanicalReduction>
    </actuator>
    <joint name="joint3">
      <hardwareInterface>EffortJointInterface</hardwareInterface>
    </joint>
  </transmission> 

<transmission name="second_to_third_trans">
    <type>transmission_interface/SimpleTransmission</type>
    <actuator name="motor4">
      <mechanicalReduction>1</mechanicalReduction>
    </actuator>
    <joint name="joint4">
      <hardwareInterface>EffortJointInterface</hardwareInterface>
    </joint>
  </transmission> 



<!-- ########################################################################### -->


<link name="world"/>



<!-- virtual link used to perform the transitional movement along z-axis (note that it has no visual tag) -->
<link name="virtual">
    <collision>
	<origin rpy="0 0 0" xyz="0 0 1"/>
      <geometry>
        <cylinder length="0.6" radius="0.1"/>
      </geometry>
    </collision>
    <inertial>
	<origin xyz="0 0 1" rpy="0 0 0"/>
      <mass value="10"/>
      <inertia ixx="0.0" ixy="0.0" ixz="0.0" iyy="1.2" iyz="0.0" izz="1.2"/>
    </inertial>
  </link> 


<joint name="z_axis_joint" type="prismatic">
        <origin xyz="0 0 0" rpy="0.0 0.0 0.0"/>
        <parent link="world" />
        <child link="virtual" />
        <axis xyz="0 0 1" />
        <limit effort="10000" lower="-1000" upper="1000" velocity="1000" />
</joint>



<!-- the basic link of the robot -->
  <link name="link1">
     <visual>
	<origin rpy="0 0 0" xyz="0 0 1"/>
      <geometry>
        <cylinder length="0.6" radius="0.1"/>
      </geometry>
      <material name="blue">
        <color rgba="0 0 .8 1"/>
      </material>
    </visual> 
    <collision>
	<origin rpy="0 0 0" xyz="0 0 1"/>
      <geometry>
        <cylinder length="0.6" radius="0.1"/>
      </geometry>
    </collision>
    <inertial>
	<origin xyz="0 0 1" rpy="0 0 0"/>
      <mass value="10"/>
      <inertia ixx="0.0" ixy="0.0" ixz="0.0" iyy="1.2" iyz="0.0" izz="1.2"/>
    </inertial>
  </link>





<!--  2nd link of the robot  -->
<link name="link2">
    <visual>
	<origin rpy="0 1.5707 1.5707" xyz="0 0.3 0"/>
      <geometry>
        <cylinder length="0.6" radius="0.1"/>
      </geometry>
      <material name="blue">
        <color rgba="0 0 .8 1"/>
      </material>
    </visual>
    <collision>
	<origin rpy="0 1.5707 1.5707" xyz="0 0.3 0"/>
      <geometry>
        <cylinder length="0.6" radius="0.1"/>
      </geometry>
    </collision>
    <inertial>
	<origin xyz="0 0.3 0" rpy="0 0 0"/>
      <mass value="10"/>
      <inertia ixx="0.0" ixy="0.0" ixz="0.0" iyy="1.2" iyz="0.0" izz="1.2"/>
    </inertial>
  </link>



<!-- 3rd link of the robot -->
<link name="link3">
    <visual>
	<origin rpy="0 1.5707 1.5707" xyz="0 -0.3 0"/>
      <geometry>
        <cylinder length="0.6" radius="0.1"/>
      </geometry>
      <material name="blue">
        <color rgba="0 0 .8 1"/>
      </material>
    </visual>
    <collision>
	<origin rpy="0 1.5707 1.5707" xyz="0 -0.3 0"/>
      <geometry>
        <cylinder length="0.6" radius="0.1"/>
      </geometry>
    </collision>
    <inertial>
	<origin xyz="0 -0.3 0" rpy="0 0 0"/>
      <mass value="10"/>
      <inertia ixx="0.0" ixy="0.0" ixz="0.0" iyy="1.2" iyz="0.0" izz="1.2"/>
    </inertial>
  </link>



<!-- 4th link of the robot and the sphere attached to it -->
<link name="link4">
    <visual>
	<origin rpy="0 0 0" xyz="0 0 -0.3"/>
      <geometry>
        <cylinder length="0.6" radius="0.1"/>
      </geometry>
      <material name="blue">
        <color rgba="0 0 .8 1"/>
      </material>
    </visual>
    <collision>
	<origin rpy="0 0 0" xyz="0 0 -0.3"/>
      <geometry>
        <cylinder length="0.6" radius="0.1"/>
      </geometry>
    </collision>
    <inertial>
	<origin xyz="0 0 -0.3" rpy="0 0 0"/>
      <mass value="10"/>
      <inertia ixx="0.0" ixy="0.0" ixz="0.0" iyy="1.2" iyz="0.0" izz="1.2"/>
    </inertial>
  </link>


  <link name="sphere1">
    <visual>
	<origin rpy="0 -0.6 0" xyz="0 0 0"/>
      <geometry>
        <sphere radius="0.1"/>
      </geometry>
    </visual>
    <collision>
	<origin rpy="0 -0.6 0" xyz="0 0 0"/>
      <geometry>
        <sphere radius="0.1"/>
      </geometry>
    </collision>
    <inertial>
	<origin xyz="0 0 0" rpy="0 0 0"/>
      <mass value="10"/>
      <inertia ixx="0.04" ixy="0.0" ixz="0.0" iyy="0.04" iyz="0.0" izz="0.04"/>
    </inertial>
  </link>


<joint name="sphere_to_link4" type="fixed">
    <parent link="link4"/>
    <child link="sphere1"/>
    <origin xyz="0 0 -0.6"/>
</joint>





<!-- 5th link of the robot and the sphere attached to it -->
<link name="link5">
    <visual>
	<origin rpy="0 0 0" xyz="0 0 -0.3"/>
      <geometry>
        <cylinder length="0.6" radius="0.1"/>
      </geometry>
      <material name="blue">
        <color rgba="0 0 .8 1"/>
      </material>
    </visual>
    <collision>
	<origin rpy="0 0 0" xyz="0 0 -0.3"/>
      <geometry>
        <cylinder length="0.6" radius="0.1"/>
      </geometry>
    </collision>
    <inertial>
	<origin xyz="0 0 -0.3" rpy="0 0 0"/>
      <mass value="10"/>
      <inertia ixx="0.0" ixy="0.0" ixz="0.0" iyy="1.2" iyz="0.0" izz="1.2"/>
    </inertial>
  </link> 



  <link name="sphere2">
    <visual>
	<origin rpy="0 0.6 0" xyz="0 0 0"/>
      <geometry>
        <sphere radius="0.1"/>
      </geometry>
    </visual>
    <collision>
	<origin rpy="0 0.6 0" xyz="0 0 0"/>
      <geometry>
        <sphere radius="0.1"/>
      </geometry>
    </collision>
    <inertial>
	<origin xyz="0 0 0" rpy="0 0 0"/>
      <mass value="10"/>
      <inertia ixx="0.04" ixy="0.0" ixz="0.0" iyy="0.04" iyz="0.0" izz="0.04"/>
    </inertial>
  </link>


<joint name="sphere_to_link5" type="fixed">
    <parent link="link5"/>
    <child link="sphere2"/>
    <origin xyz="0 0 -0.6"/>
</joint>




<!-- joint that performs the planar movement of the base link (link1) of the robot, which mantains the movement of the robot inside yz plane -->
    <joint name="zy_planar_joint" type="prismatic">
        <origin xyz="0 0 0" rpy="0.0 0.0 0.0"/>
        <parent link="virtual" />
        <child link="link1" />
        <axis xyz="0 1 0" />
        <limit effort="10000" lower="-1000" upper="1000" velocity="1000" />
    </joint>

<!-- ################################################################################################################### -->


<!-- other joints of the robot -->
<joint name="joint1" type="${type_of_joint}">
    <parent link="link1"/>
    <child link="link2"/>
    <origin xyz="0 0 0.7"/>
    <axis rpy="0 0 0" xyz="1 0 0"/>
    <limit lower="-3.1416" upper="3.1416" effort="10000" velocity="1000"/>
    <dynamics friction="${friction}"/>
  </joint>


<joint name="joint2" type="${type_of_joint}">
    <parent link="link1"/>
    <child link="link3"/>
    <origin xyz="0 0 0.7"/>
    <axis rpy="0 0 0" xyz="1 0 0"/>
    <limit lower="-3.1416" upper="3.1416" effort="10000" velocity="1000"/>
    <dynamics friction="${friction}"/>
  </joint>


<joint name="joint3" type="${type_of_joint}">
    <parent link="link3"/>
    <child link="link4"/>
    <origin xyz="0 -0.6 0"/>
    <axis rpy="0 0 0" xyz="1 0 0"/>
    <limit lower="-3.1416" upper="3.1416" effort="10000" velocity="1000"/>
    <dynamics friction="${friction}"/>
  </joint>


<joint name="joint4" type="${type_of_joint}">
    <parent link="link2"/>
    <child link="link5"/>
    <origin xyz="0 0.6 0"/>
    <axis rpy="0 0 0" xyz="1 0 0"/>
    <limit lower="-3.1416" upper="3.1416" effort="10000" velocity="1000"/>
     <dynamics friction="${friction}"/> 
  </joint>

<!-- ##################################################################################################### -->



  
</robot>
