<?xml version="1.0"?>
<robot name="m2wr" xmlns:xacro="http://www.ros.org/wiki/xacro">
  <material name="black">
    <color rgba="0.0 0.0 0.0 1.0"/>
  </material>
  <material name="blue">
    <color rgba="0.203125 0.23828125 0.28515625 1.0"/>
  </material>
  <material name="green">
    <color rgba="0.0 0.8 0.0 1.0"/>
  </material>
  <material name="grey">
    <color rgba="0.2 0.2 0.2 1.0"/>
  </material>
  <material name="orange">
    <color rgba="1.0 0.423529411765 0.0392156862745 1.0"/>
  </material>
  <material name="brown">
    <color rgba="0.870588235294 0.811764705882 0.764705882353 1.0"/>
  </material>
  <material name="red">
    <color rgba="0.80078125 0.12890625 0.1328125 1.0"/>
  </material>
  <material name="white">
    <color rgba="1.0 1.0 1.0 1.0"/>
  </material>
  
    <gazebo reference="link1">
    <material>Gazebo/Orange</material>
  </gazebo>
<gazebo reference="link2">
    <material>Gazebo/Blue</material>
  </gazebo>
<gazebo reference="link3">
    <material>Gazebo/Red</material>
  </gazebo>
<gazebo reference="link4">
    <material>Gazebo/Black</material>
  </gazebo>
<gazebo reference="link5">
    <material>Gazebo/Black</material>
  </gazebo>



<gazebo>
    <plugin name="gazebo_ros_control" filename="libgazebo_ros_control.so">
      <robotNamespace>/simple_model</robotNamespace>
    </plugin>
  </gazebo>

<transmission name="first_to_second_trans">
    <type>transmission_interface/SimpleTransmission</type>
    <actuator name="motor1">
      <mechanicalReduction>1</mechanicalReduction>
    </actuator>
    <joint name="joint1">
      <hardwareInterface>EffortJointInterface</hardwareInterface>
    </joint>
  </transmission>

<transmission name="second_to_third_trans">
    <type>transmission_interface/SimpleTransmission</type>
    <actuator name="motor2">
      <mechanicalReduction>1</mechanicalReduction>
    </actuator>
    <joint name="joint2">
      <hardwareInterface>EffortJointInterface</hardwareInterface>
    </joint>
  </transmission>


<link name="world"/>

  <joint name="fixed" type="fixed">
    <parent link="world"/>
    <child link="link1"/>
  </joint>


  <link name="link1">
    <visual>
	<origin rpy="0 1.5707 1.5707" xyz="0 0.3 0.1"/>
      <geometry>
        <cylinder length="0.6" radius="0.1"/>
      </geometry>
      <material name="blue">
        <color rgba="0 0 .8 1"/>
      </material>
    </visual>
    <collision>
	<origin rpy="0 1.5707 1.5707" xyz="0 0.3 0.1"/>
      <geometry>
        <cylinder length="0.6" radius="0.1"/>
      </geometry>
    </collision>
    <inertial>
	<origin xyz="0 0.3 0.1" rpy="0 0 0"/>
      <mass value="10"/>
      <inertia ixx="1.2" ixy="0.0" ixz="0.0" iyy="0.0" iyz="0.0" izz="1.2"/>
    </inertial>
  </link>


<link name="link2">
    <visual>
	<origin rpy="0 1.5707 1.5707" xyz="0 0.3 0.1"/>
      <geometry>
        <cylinder length="0.6" radius="0.1"/>
      </geometry>
      <material name="blue">
        <color rgba="0 0 .8 1"/>
      </material>
    </visual>
    <collision>
	<origin rpy="0 1.5707 1.5707" xyz="0 0.3 0.1"/>
      <geometry>
        <cylinder length="0.6" radius="0.1"/>
      </geometry>
    </collision>
    <inertial>
	<origin xyz="0 0.3 0.1" rpy="0 0 0"/>
      <mass value="10"/>
      <inertia ixx="1.2" ixy="0.0" ixz="0.0" iyy="0.0" iyz="0.0" izz="1.2"/>
    </inertial>
  </link>


<link name="link3">
    <visual>
	<origin rpy="0 1.5707 0" xyz="0.3 0 0.1"/>
      <geometry>
        <cylinder length="0.6" radius="0.1"/>
      </geometry>
      <material name="blue">
        <color rgba="0 0 .8 1"/>
      </material>
    </visual>
     <collision>
	<origin rpy="0 1.5707 0" xyz="0.3 0 0.1"/>
      <geometry>
        <cylinder length="0.6" radius="0.1"/>
      </geometry>
    </collision> 
    <inertial>
	<origin xyz="0.3 0 0.1" rpy="0 0 0"/>
      <mass value="10"/>
      <inertia ixx="1.2" ixy="0.0" ixz="0.0" iyy="0.0" iyz="0.0" izz="1.2"/>
    </inertial>
  </link>


<link name="link4">
    <visual>
	<origin rpy="0 1.5707 0" xyz="0.3 0 0.1"/>
      <geometry>
        <cylinder length="0.6" radius="0.1"/>
      </geometry>
      <material name="blue">
        <color rgba="0 0 .8 1"/>
      </material>
    </visual>
    <collision>
	<origin rpy="0 1.5707 0" xyz="0.3 0 0.1"/>
      <geometry>
        <cylinder length="0.6" radius="0.1"/>
      </geometry>
    </collision>
    <inertial>
	<origin xyz="0.3 0 0.1" rpy="0 0 0"/>
      <mass value="10"/>
      <inertia ixx="1.2" ixy="0.0" ixz="0.0" iyy="0.0" iyz="0.0" izz="1.2"/>
    </inertial>
  </link> 


<link name="link5">
    <visual>
	<origin rpy="0 1.5707 1.5707" xyz="0 0.3 0.1"/>
      <geometry>
        <cylinder length="0.6" radius="0.1"/>
      </geometry>
      <material name="blue">
        <color rgba="0 0 .8 1"/>
      </material>
    </visual>
    <collision>
	<origin rpy="0 1.5707 1.5707" xyz="0 0.3 0.1"/>
      <geometry>
        <cylinder length="0.6" radius="0.1"/>
      </geometry>
    </collision>
    <inertial>
	<origin xyz="0 0.3 0.1" rpy="0 0 0"/>
      <mass value="10"/>
      <inertia ixx="1.2" ixy="0.0" ixz="0.0" iyy="0.0" iyz="0.0" izz="1.2"/>
    </inertial>
  </link>

<joint name="joint4" type="continuous">
    <parent link="link1"/>
    <child link="link2"/>
    <origin xyz="0 0.6 0"/> 
    <axis rpy="0 0 0" xyz="0 0 1"/> 
    <!-- <limit effort="10000" velocity="1000"/> 
    <joint_properties damping="1.0" friction="1.0"/> -->
  </joint>


<joint name="joint3" type="continuous">
    <parent link="link1"/>
    <child link="link3"/>
    <origin xyz="0 0.6 0"/>
    <axis rpy="0 0 0" xyz="0 0 1"/> 
   <!-- <limit effort="10000" velocity="1000"/> 
    <joint_properties damping="1.0" friction="1.0"/> -->
  </joint>


<joint name="joint2" type="continuous">
    <parent link="link3"/>
    <child link="link4"/>
    <origin xyz="0.6 0 0"/>
     <axis rpy="0 0 0" xyz="0 0 1"/> 
    <!-- <limit effort="10000" velocity="1000"/> 
    <joint_properties damping="1.0" friction="1.0"/> -->
 </joint>


<joint name="joint1" type="continuous">
    <parent link="link2"/>
    <child link="link5"/>
    <origin xyz="0 0.6 0"/>
     <axis rpy="0 0 0" xyz="0 0 1"/> 
    <!-- <limit effort="10000" velocity="1000"/> 
    <joint_properties damping="1.0" friction="1.0"/> -->
  </joint>



  
</robot>
